Workbook

Sheet 使用说明
A1: 《自驾旅行预算测算表》
A2: 填写目的地、天数、人数、里程、车型、住宿、餐饮、门票等信息后，可自动估算旅行总预算、人均预算、日均预算、车辆成本占比和出行前建议准备资金。
A3: 使用步骤
A4: 1 | B4: 先填写基础信息。
A5: 2 | B5: 再填写车辆与交通费用。
A6: 3 | B6: 继续填写住宿、餐饮、景区游玩和其他费用。
A7: 4 | B7: 查看总预算汇总和智能提示。
A8: 5 | B8: 根据预算结果调整车型、住宿、路线或游玩项目。
A9: 说明 | B9: 押金不计入实际花费，但会计入“出行前建议准备资金”。
A10: 免责声明 | B10: 预算仅供参考，实际费用以租车平台、酒店、景区、油价、电价和当地情况为准。
A11: 更多租车自驾攻略：小红书 @你的账号名

Sheet 预算填写表
A1: 《自驾旅行预算测算表》
A2: 区域 A：基础信息
A3: 目的地 | C3: 例：新疆伊犁 / 青岛 / 川西
A4: 出发城市 | C4: 例：重庆 / 成都 / 上海
A5: 出行天数 | C5: 填写数字
A6: 出行人数 | C6: 填写数字
A7: 租车天数 | C7: 填写数字
A8: 预计总里程/km | C8: 填写预计自驾总里程
A9: 能源类型 | B9: 油车 | C9: 下拉选择：油车 / 新能源 / 混动
A10: 百公里油耗/L | C10: 油车/混动填写
A11: 百公里电耗/kWh | C11: 新能源填写
A12: 油价/元每升 | C12: 当地预计油价
A13: 电价/元每度 | C13: 快充/慢充可取平均值
A14: 出行预算风格 | B14: 适中 | C14: 下拉选择：省钱 / 适中 / 舒适
A16: 区域 B：车辆与交通费用
A17: 费用项目 | B17: 单价 | C17: 数量 | D17: 小计 | E17: 备注
A18: 租车日租金 | C18: =$B$7 | D18: =IF(OR(B18="",C18=""),"",B18*C18) | E18: 单价 × 租车天数
A19: 基础服务费 | C19: =$B$7 | D19: =IF(OR(B19="",C19=""),"",B19*C19) | E19: 可按天填写，如平台另收服务费
A20: 基础保险 | C20: =$B$7 | D20: =IF(OR(B20="",C20=""),"",B20*C20) | E20: 单价 × 租车天数
A21: 补充保险 | C21: =$B$7 | D21: =IF(OR(B21="",C21=""),"",B21*C21) | E21: 单价 × 租车天数
A22: 异地还车费 | C22: 1 | D22: =IF(OR(B22="",C22=""),"",B22*C22) | E22: 如无异地还车填 0
A23: 油费/电费 | B23: =IF($B$9="新能源",$B$13,$B$12) | C23: =IF($B$9="新能源",$B$8/100*$B$11,$B$8/100*$B$10) | D23: =IF($B$9="新能源",$B$8/100*$B$11*$B$13,$B$8/100*$B$10*$B$12) | E23: 根据能源类型自动估算
A24: 高速费/过路费 | C24: 1 | D24: =IF(OR(B24="",C24=""),"",B24*C24) | E24: 可填预计总额
A25: 停车费 | C25: =$B$5 | D25: =IF(OR(B25="",C25=""),"",B25*C25) | E25: 可按每天全车费用
A26: 洗车费 | C26: 1 | D26: =IF(OR(B26="",C26=""),"",B26*C26) | E26: 还车前如需洗车
A27: 车辆押金 | C27: 1 | D27: =IF(OR(B27="",C27=""),"",B27*C27) | E27: 不计入旅行总预算，计入临时占用资金
A28: 违章押金 | C28: 1 | D28: =IF(OR(B28="",C28=""),"",B28*C28) | E28: 不计入旅行总预算，计入临时占用资金
A29: 区域 C：住宿餐饮费用
A30: 费用项目 | B30: 单价 | C30: 数量 | D30: 小计 | E30: 备注
A31: 酒店/民宿每晚总价 | C31: =MAX($B$5-1,0) | D31: =IF(OR(B31="",C31=""),"",B31*C31) | E31: 住宿费用 = 每晚总价 ×（出行天数 - 1）
A32: 早餐 | C32: =$B$6*$B$5 | D32: =IF(OR(B32="",C32=""),"",B32*C32) | E32: 人均单价 × 人数 × 天数
A33: 午餐 | C33: =$B$6*$B$5 | D33: =IF(OR(B33="",C33=""),"",B33*C33) | E33: 人均单价 × 人数 × 天数
A34: 晚餐 | C34: =$B$6*$B$5 | D34: =IF(OR(B34="",C34=""),"",B34*C34) | E34: 人均单价 × 人数 × 天数
A35: 零食饮料 | C35: =$B$5 | D35: =IF(OR(B35="",C35=""),"",B35*C35) | E35: 按每日全车费用计算
A36: 咖啡奶茶 | C36: =$B$6*$B$5 | D36: =IF(OR(B36="",C36=""),"",B36*C36) | E36: 可按人均每天估算
A37: 特色餐/大餐 | D37: =IF(OR(B37="",C37=""),"",B37*C37) | E37: 单次全车费用 × 次数
A38: 区域 D：景区游玩费用
A39: 费用项目 | B39: 单价 | C39: 数量 | D39: 小计 | E39: 备注
A40: 景区门票 | C40: =$B$6 | D40: =IF(OR(B40="",C40=""),"",B40*C40) | E40: 人均门票 × 人数
A41: 景区区间车 | C41: =$B$6 | D41: =IF(OR(B41="",C41=""),"",B41*C41) | E41: 人均区间车 × 人数
...

Sheet 总预算汇总
A1: 总预算汇总
A2: 汇总项 | B2: 金额 | C2: 说明
A3: 车辆与交通实际费用 | B3: =SUM('预算填写表'!D18:D26) | C3: 不包含车辆押金和违章押金
A4: 住宿费用 | B4: ='预算填写表'!D31 | C4: 酒店/民宿每晚总价 × 晚数
A5: 餐饮费用 | B5: =SUM('预算填写表'!D32:D37) | C5: 早餐、午餐、晚餐、零食、咖啡、特色餐
A6: 景区游玩费用 | B6: =SUM('预算填写表'!D40:D47) | C6: 门票、区间车、索道、娱乐项目等
A7: 大交通费用 | B7: ='预算填写表'!D50 | C7: 往返机票/高铁
A8: 其他费用 | B8: =SUM('预算填写表'!D51:D55) | C8: 市内交通、购物、装备、流量等
A9: 应急预算 | B9: ='预算填写表'!D56 | C9: 除押金外基础总预算 × 10%
A10: 旅行总预算 | B10: =SUM(B3:B9) | C10: 所有实际花费合计，不含押金
A11: 人均预算 | B11: =IFERROR(B10/'预算填写表'!B6,0) | C11: 旅行总预算 / 出行人数
A12: 日均预算 | B12: =IFERROR(B10/'预算填写表'!B5,0) | C12: 旅行总预算 / 出行天数
A13: 人均日预算 | B13: =IFERROR(B10/'预算填写表'!B6/'预算填写表'!B5,0) | C13: 旅行总预算 / 人数 / 天数
A14: 临时占用资金 | B14: =SUM('预算填写表'!D27:D28) | C14: 车辆押金 + 违章押金
A15: 出行前建议准备资金 | B15: =B10+B14 | C15: 旅行总预算 + 临时占用资金
A16: 更多租车自驾攻略：小红书 @你的账号名

Sheet 智能预算判断
A1: 智能预算判断
A2: 判断项 | B2: 结果 | C2: 说明
A3: 人均预算等级 | B3: =IF('总预算汇总'!B11<2000,"经济型",IF('总预算汇总'!B11<5000,"适中型",IF('总预算汇总'!B11<8000,"舒适型","高预算型"))) | C3: 按人均预算自动分层
A4: 车辆成本占比 | B4: =IFERROR('总预算汇总'!B3/'总预算汇总'!B10,0) | C4: 车辆与交通实际费用 / 旅行总预算
A5: 车辆成本判断 | B5: =IF(B4<30%,"车辆成本合理",IF(B4<45%,"车辆成本偏高，但可接受","车辆成本较高，建议降低车型等级、减少租车天数或避免异地还车")) | C5: 超过 45% 时建议重点优化车辆成本
A6: 预算优化建议：车辆 | B6: =IF(B4>=30%,"建议降低车型等级、避开节假日、减少异地还车或提前预订。","车辆成本占比正常，可继续对比车型和保险。") | C6: 车辆成本偏高时自动提示
A7: 预算优化建议：住宿 | B7: =IFERROR(IF('总预算汇总'!B4/'总预算汇总'!B10>=35%,"建议提前订房、错峰出行、选择县城或非核心景区住宿。","住宿费用占比正常。"),"住宿费用占比正常。") | C7: 住宿占比高时自动提示
A8: 预算优化建议：景区 | B8: =IFERROR(IF('总预算汇总'!B6/'总预算汇总'!B10>=20%,"建议提前确认门票、区间车、索道等费用，避免现场超预算。","景区游玩费用占比正常。"),"景区游玩费用占比正常。") | C8: 景区费用较高时自动提示
A9: 新能源长里程提醒 | B9: =IF(AND('预算填写表'!B9="新能源",'预算填写表'!B8>=800),"建议提前规划充电节点，预留补能时间。","当前无需额外新能源长里程提醒。") | C9: 新能源且总里程较高时自动提示
A10: 适合的出行风格 | B10: =IF('总预算汇总'!B11<2000,"适合学生党/轻预算路线，优先控制住宿和车型。",IF('总预算汇总'!B11<5000,"适合情侣/朋友常规自驾，预算弹性较好。",IF('总预算汇总'!B11<8000,"适合舒适型路线，可提升住宿或车型。","适合高预算深度游，建议重点确认保险和应急资金。"))) | C10: 结合人均预算给出路线风格参考
A11: 更多租车自驾攻略：小红书 @你的账号名

Sheet 示例预算
A1: 《自驾旅行预算测算表》示例预算：新疆伊犁 6 天 2 人
A2: 基础信息
A3: 目的地 | B3: 新疆伊犁 | C3: 出发城市 | D3: 重庆
A4: 出行天数 | B4: 6 | C4: 出行人数 | D4: 2
A5: 租车天数 | B5: 6 | C5: 预计总里程/km | D5: 1600
A6: 能源类型 | B6: 油车 | C6: 百公里油耗/L | D6: 9
A7: 油价/元每升 | B7: 8
A9: 费用项目 | B9: 单价 | C9: 数量 | D9: 小计 | E9: 备注
A10: 租车日租金 | B10: 400 | C10: 6 | D10: =B10*C10 | E10: 租车日租金 × 租车天数
A11: 基础保险 | B11: 50 | C11: 6 | D11: =B11*C11 | E11: 50 元/天
A12: 补充保险 | B12: 80 | C12: 6 | D12: =B12*C12 | E12: 80 元/天
A13: 油费 | D13: =1600/100*9*8 | E13: 1600/100 × 9L × 8元
A14: 高速费/过路费 | B14: 500 | C14: 1 | D14: =B14*C14 | E14: 预计总额
A15: 停车费 | B15: 20 | C15: 6 | D15: =B15*C15 | E15: 20 元/天
A16: 酒店每晚总价 | B16: 350 | C16: 5 | D16: =B16*C16 | E16: 6 天行程住 5 晚
A17: 早餐 | B17: 20 | C17: 12 | D17: =B17*C17 | E17: 20 元/人/天 × 2 人 × 6 天
A18: 午餐 | B18: 40 | C18: 12 | D18: =B18*C18 | E18: 40 元/人/天 × 2 人 × 6 天
A19: 晚餐 | B19: 70 | C19: 12 | D19: =B19*C19 | E19: 70 元/人/天 × 2 人 × 6 天
A20: 景区门票和区间车合计 | B20: 600 | C20: 2 | D20: =B20*C20 | E20: 600 元/人
A21: 往返机票 | B21: 1800 | C21: 2 | D21: =B21*C21 | E21: 1800 元/人
A22: 应急预算 | C22: 10% | D22: =SUM(D10:D21)*10% | E22: 自动计算
A23: 示例旅行总预算 | D23: =SUM(D10:D22) | E23: 不含租车押金/违章押金
A24: 示例人均预算 | D24: =D23/2 | E24: 总预算 / 2 人
A25: 更多租车自驾攻略：小红书 @你的账号名

Sheet PDF导出建议版式
A1: PDF 导出建议版式
A2: 推荐导出范围 | B2: 使用说明 + 总预算汇总 + 智能预算判断 + 示例预算，可做领取前预览；完整版包含预算填写表。
A3: 页面设置 | B3: A4 竖向；页边距选“窄”；缩放选“将所有列调整为一页”；预算填写表允许多页。
A4: 预览顺序 | B4: 第 1 页放使用说明，第 2 页放总预算汇总，第 3 页放智能预算判断，第 4 页放示例预算。
A5: 小红书截图 | B5: 建议截“旅行总预算 / 人均预算 / 出行前建议准备资金”和“预算优化建议”两块。
A6: 品牌露出 | B6: 导出前把底部“小红书 @你的账号名”替换为你的真实账号。
A7: 更多租车自驾攻略：小红书 @你的账号名
